2023-10-15 20:55:06,929 ERROR: Exception on /favicon.ico [GET] [in /home/terry/microblog/venv/lib/python3.10/site-packages/flask/app.py:1414]
Traceback (most recent call last):
  File "/home/terry/microblog/venv/lib/python3.10/site-packages/flask/app.py", line 2190, in wsgi_app
    response = self.full_dispatch_request()
  File "/home/terry/microblog/venv/lib/python3.10/site-packages/flask/app.py", line 1486, in full_dispatch_request
    rv = self.handle_user_exception(e)
  File "/home/terry/microblog/venv/lib/python3.10/site-packages/flask/app.py", line 1482, in full_dispatch_request
    rv = self.preprocess_request()
  File "/home/terry/microblog/venv/lib/python3.10/site-packages/flask/app.py", line 1974, in preprocess_request
    rv = self.ensure_sync(before_func)()
  File "/home/terry/microblog/app/routes.py", line 235, in before_request
    g.locale = str(get_locale())
  File "/home/terry/microblog/venv/lib/python3.10/site-packages/flask_babel/__init__.py", line 222, in get_locale
    babel = current_app.extensions['babel']
KeyError: 'babel'
2023-10-15 21:04:44,755 INFO: Microblog startup [in /home/terry/microblog/app/__init__.py:65]
